Workbook
Name \0: #REF!
Name \0: #REF!
Name \0: #REF!
Name \a: #REF!
Name \a: #REF!
Name \a: #REF!
Name \b: #REF!
Name \b: #REF!
Name \b: #REF!
Name \C: #REF!
Name \C: #REF!
Name \C: #REF!
Name \g: #REF!
Name \g: #REF!
Name \g: #REF!
Name \i: #REF!
Name \i: #REF!
Name \i: #REF!
Name \l: #REF!
Name \l: #REF!
Name \l: #REF!
Name \m: #REF!
Name \m: #REF!
Name \m: #REF!
Name \o: #REF!
Name \o: #REF!
Name \o: #REF!
Name \p: #REF!
Name \p: #REF!
Name \p: #REF!
Name \q: #REF!
Name \q: #REF!
Name \q: #REF!
Name \r: #REF!
Name \r: #REF!
Name \r: #REF!
Name \s: #REF!
Name \s: #REF!
Name \s: #REF!
Name _____________________________________b1: City&" "&State
Name _____________________________________b1: [0]!City&" "&State
Name _____________________________________b1: City&" "&State
Name _____________________________________loc1: City&" "&State
Name _____________________________________loc1: [0]!City&" "&State
Name _____________________________________loc1: City&" "&State
Name _______________________________b1: City&" "&State
Name _______________________________b1: [0]!City&" "&State
Name _______________________________b1: City&" "&State
Name _______________________________loc1: City&" "&State
Name _______________________________loc1: [0]!City&" "&State
Name _______________________________loc1: City&" "&State
Name _____________________________b1: City&" "&State
Name _____________________________b1: [0]!City&" "&State
Name _____________________________b1: City&" "&State
Name _____________________________loc1: City&" "&State
Name _____________________________loc1: [0]!City&" "&State
Name _____________________________loc1: City&" "&State
Name ____________________________b1: City&" "&State
Name ____________________________b1: [0]!City&" "&State
Name ____________________________b1: City&" "&State

Sheet C&I Summary
C7: Office Address :-C-19, 2nd Floor (Above SBI Bank)
C8: Near Mrignaini Chowk, Dilshad Colony, New Delhi-110095
C9: Specialist in Space planing, Interior Decorations & Management, Project
C10: work and all type of office maintenance activities.
A13: Ms: Compass - Chennai | D13: Date : 29-12-2025
A14: CIVIL & INTERIORS SUMMARY
A15: S.no | B15: Code | C15: Description | D15: Amount
A17: A | B17: Dem | C17: Demolition Works | D17: ='C&I'!G29 -> 166832
A19: B | B19: Mas | C19: Masonry Works | D19: ='C&I'!G42 -> 1632674.9
A21: C | B21: PL | C21: Plastering | D21: ='C&I'!G53 -> 716691
A23: D | B23: MIS | C23: Miscellneous Works | D23: ='C&I'!G75 -> 662937.97
A25: E | B25: PA | C25: Painting Works | D25: ='C&I'!G85 -> 185762.16
A27: F | B27: FC | C27: False Ceiling Works | D27: ='FC - BOQ'!G34 -> 3655946.7
A29: G | B29: FLR | C29: Flooring Works | D29: ='FLR - BOQ'!G91 -> 5687973
A31: H | B31: JNR | C31: Joinery | D31: ='JNR-BOQ'!G80 -> 774642.2
A33: I | B33: FUR | C33: Work Station and Chairs | D33: =FURN!G13 -> 167440
C35: TOTAL | D35: =SUM(D17:D33) -> 13650900

Sheet C&I
C2: BILL OF QUANTITIES
A3: S.no | B3: Item No | C3: Description | D3: Unit | E3: Qty | F3: Rate | G3: Amount
A5: A | B5: Dem | C5: Demolition Works
C6: Notes: 1. Before any physical work begins, a detailed plan and a comprehensive survey of the site shall have to be done by the contractor. 2. Confirm the location and type of the structure to be demolished e.g., masonry, reinforced concrete etc 3. Photograph the existing structure and surrounding properties to document their condition before work starts. 4. Note the location of adjacent buildings, public thoroughfares, and utilities to be aware of potential impacts. 5. Identify and document any hazardous materials 6. Verify whether all electrical, gas, water, and telecommunication lines serving the structure have been safely disconnected and locked out. 7. Note that services needed for the demolition work itself (e.g., temporary power) are isolated and secured. 8. Note that all necessary permits and approvals from local authorities, including any required show cause notices, have been obtained. 9. Ensure a Method Statement detailing the work sequence and safety plan has been approved by the site incharge / engineer. 10. Outline which materials will be salvaged or recycled to minimize waste and reduce disposal costs. 11. Confirm legal and environmentally compliant procedures for disposing of all waste. 12. Note that all workers are wearing appropriate Personal Protective Equipment (PPE). 13. Verify the stability of remaining structures.
A8: 1 | B8: DEM -01 | C8: Demolishing blockwork
C9: Breaking/Demolishing of existing solid block masonry wall . The rate shall be inclusive of all lead, lift, shifting, necessary scaffoldings, and disposal of debris outside site premises or dumping inside the site premises at location where directed for filling purposes as per the directions / instructions of site in charge. Care shall have to be taken while demolishing external / peripheral walls. Works shall be carried out at any level .Vendor shall provide sufficient covering to flooring to protect from getting damaged. | D9: Cum | E9: 20 | F9: 3410 | G9: =F9*E9 -> 68200
F10: 0
A11: 2 | B11: DEM - 02 | C11: Removing and stacking the metallic rolling shutters and windows and stacking them at a place where directed as per the instructions of Engineer in charge. Care shall be taken to see that the area is protected. The rate shall include suitable scaffolding, tools, tackles, segregating usable and non usable parts and stackng the usable parts safely and disposing the non usable ones then and there. Rate shall include making good of the damaged surfaces if any while dismantling. Proper care shall have to be taken while dismantling the motorised rolling shutters from elecrical connections. | D11: LS | E11: QRO | F11: 97440
B12: A | C12: Rolling Shutters | F12: 0
F13: 0
C14: R1 - 0.89x3.35 | F14: 0
C15: R4 - 2.95x3.35 | F15: 0
C16: R5 - 1.20x3.35 | F16: 0
C17: R7 - 4.10x3.35 | F17: 0
C18: R9 - 3.63x4.22 | F18: 0
B19: B | C19: Windows | F19: 0
F20: 0
C21: R2 - 0.9x1.2 | F21: 0
C22: R3 - 0.93x1.2 | F22: 0
C23: R6 - 0.95x1.2 | F23: 0
C24: R8 - 2.1x1.2 | F24: 0
F25: 0
A26: 3 | B26: DEM - 03 | C26: Removing and stacking the metallic sheets from the existing shed roofs and stacking them at a place where directed as per the instructions of Engineer in charge. Care shall be taken to see that the area is protected. The rate shall include suitable scaffolding, tools, tackles, segregating usable and non usable parts and stackng the usable parts safely and disposing the non usable ones then and there as directed by the site incharge. Rate shall include making good of the damaged surfaces if any while dismantling. Proper care shall have to be taken while dismantling the shed roofs from elecrical connections / services | D26: LS | E26: 1 | F26: 98632 | G26: =F26*E26 -> 98632
C29: Demolition Works - Sub Total | G29: =SUM(G9:G28) -> 166832
A31: B | B31: MAS | C31: Masonry Works
A33: 4 | B33: MAS 01 | C33: Providing and constructing solid concrete block masonry walls of varying thickness as specified in the drawing in cement mortar(1 cement :6 M.sand)using precast blocks of 400 x 200/ 100/150 x 200mm size with minimum crushing strength of 35 kg/sq. cm for construction with necessary scaffolding, staging, striking and raking out joints to at least 10mm depth, with all lead and lift at all levels, curing, loading and unloading, transportation and all other incidental charges etc., complete as directed by the Engineer-in-charge.
D34: Cum | E34: 195 | F34: 8178 | G34: =F34*E34 -> 1594710
F35: 0
A36: 5 | B36: MAS 02 | C36: Providing and constructing solid concrete block masonry walls of 200mm thickness as specified in the drawing in cement mortar(1 cement :6 M.sand)using precast blocks of 400 x 200 x 200mm size with minimum crushing strength of 35 kg/sq. cm for construction with necessary scaffolding, staging, striking and raking out joints to at least 10mm depth, with all lead and lift at all levels, curing, loading and unloading, transportation and all other incidental charges etc., complete as directed by the Engineer-in-charge. | F36: 0
D37: Sqm | E37: 1260 | F37: 0 | G37: =F37*E37 -> 0
F38: 0
A39: 6 | B39: MAS 03 | C39: Providing and constructing solid concrete block masonry walls of 100mm thickness as specified in the drawing in cement mortar(1 cement :6 M.sand)using precast blocks of 400 x 100 x 200mm size with minimum crushing strength of 35 kg/sq. cm for construction with necessary scaffolding, staging, striking and raking out joints to at least 10mm depth, with all lead and lift at all levels, curing, loading and unloading, transportation and all other incidental charges etc., complete as directed by the Engineer-in-charge. Rate shall include providing 75mm thk cement concrete band with 8mm dia reinforcement rods at every 1m interval. | F39: 0
D40: Sqm | E40: 24.12 | F40: 1574 | G40: =F40*E40 -> 37964.88
C42: Masonry Works - Sub Total | G42: =SUM(G34:G41) -> 1632674.9
A44: C | B44: PL | C44: Plastering Works
A46: 7 | B46: PL 01 | C46: Preparing the surface, Providing & applying plastering to internal masonry walls, columns, beams, jambs etc., 12mm thick in CM 1:6 (1 cement: 6 fine sand) with lime rendering in line at all levels including hacking to RCC surfaces, providing 150 mm wide GI plaster mesh of Arpitha or equivalent approved make in the junctions of the masonry & RCC works, over electrical conduiting and wherever applicable as per manufacturer's specifications, plastering the mesh in CM 1:2. The work shall include cost of materials, labour, curing, all lead and lifts at all levels, loading and unloading, scaffolding and all other incidental charges etc., complete and as directed by the Engineer-in-charge. | D46: Sqm | E46: 564 | F46: 419 | G46: =F46*E46 -> 236316
F47: 0
A48: 8 | B48: PL 02 | C48: Preparing the surface, providing & applying Sponge finish Plastering for external walls in two layers with base coat 12mm thick in CM 1:6 & finishing coat 8mm thick in CM 1:4 laid in panels with jointless finish as per design including Water Proofing Compound of approved make, cement punning of cornices/projection/grooves, drip mould of all shape and sizes, fixing of 150 mm wide GI plaster mesh Arpitha or equivalent approved make in the junctions of the masonry & R.C.C work, over electrical conduiting, & wherever applicable as per manufacturer's specifications and plastering the mesh in CM 1:2. The work shall include cost of materials, labour, curing,approved waterproofing chemical, all lead and lifts at all levels, loading and unloading, scaffolding and all other incidental charges etc. , complete and as directed by the Engineer-in-charge. The rate to include providing grooves , wherever required as per the drawings. | D48: Sqm | E48: QRO | F48: 0
F49: 0
A50: 9 | B50: PL 03 | C50: Providing Rough Plastering for Tile Dado Backing in CM 1:6, 12mm thick for fixinf tile & granite slabs, marble, at all levels including rough finishing to line and plumb , the cost of scaffolding, curing, Lead & lifts etc.. Complete for walls including scarifying the surface to receive the tiles. Cost to include supplying & fixing the plaster mesh made out of galvanized iron of nominal thickness 0.35mm with a Zinc coating of 120gms/sqmtr at the RCC and Masonry interface, with corner bead at column corners, wall corners with Galvanized nails etc.. wherever called for required size . | D50: Sqm | E50: 1575 | F50: 305 | G50: =F50*E50 -> 480375
...

Sheet FC - BOQ
C1: BILL OF QUANTITIES
A2: S.no | B2: Item No | C2: Description | D2: Unit | E2: Qty | F2: Rate | G2: Amount
A4: F | B4: FC | C4: False Ceiling Works
C5: Notes: The rates quoted shall be inclusive of all materials, transport, loading unloading and all taxes thereon. The rate mentioned is the maximum and in no way should exceed, the one mentioned. Details of the items under this schedule shall be read in conjunction with the corresponding specifications, drawings and other Tender Documents. The work shall be carried out as per the drawings, specifications, description of the items in the schedule and / or architects instructions. Items of work provided in this schedule but not covered in the specifications shall be executed strictly as per the instructions of the project manager/architect. Unless specifically mentioned otherwise in the contract, the tenderer shall quote for the finished items and shall provide for the complete cost towards labour, materials, plant and machinery, operational costs, levies, taxes, transport, repairs, rectification etc on request from the Client. The quantities of the various items mentioned in the schedule in the schedule of items may vary up to any extent or be deleted altogether. The contractor, in his own interest, should get an indication of the probable extent of the work. The rates quoted shall be inclusive of all mock-ups, associated samples, providing templates for different types of light fixture/ other MEP fixture prior to any mass production or procurement as per complete satisfaction of the Client and Architect. Inclusive of dismantling, demolishing and carting the material and making good of
A7: 1 | B7: FC 01 | C7: Gypsum False Ceiling Works with Grid
C8: Providing and fixing Gypsum False Ceiling of which includes G.I.Perimeter Channels of size .55mm thick (having One Flange of 20mm. and another flange of 30mm and a web of 27mm) along with perimeter of ceiling, screw fixed to brick wall / partition with the help of Nylon sleeves and screws at 610mm centres. Then suspending G.I. intermediate channels of size 45mm (0.9mm thick with 2 flanges of 15mm each) from the soffit at 1220mm centres with ceiling angle of width 25mm X 10mm X 0.55mm thick fixed to soffit with G.I. cleat and steel expansion fasteners. Ceiling section of 0.55mm thick having knurled web of 51.5mm and 2 flanges of 26mm each with lips of 10.5mm are then fixed to the intermediate channel with the help of connecting clips and in direction perpendicular to the intermediate channel at 450 mm centres.
C9: 12.5mm tapered edge Gypboard (conforming to IS 2095-1982) is then screw fixed to ceiling section with 25mm dry wall Philips screws at 230mm centres. Screw fixing is done mechanically with drilling machine with suitable attachment. Finally tapered edges of the Gyp boards are to be jointed and finished so as to have a flush look which includes filling and finishing with jointing compound, paper tape etc complete as per the recommended practices of India Gypsum. Rate to be included all kinds of profiles and cut outs required for light fixtures, Speakers, Smoke detector, trap doors and AC grill , 6mm plywood templates in the ceiling | D9: Sqm | E9: 573.3835 | F9: 940 | G9: =F9*E9 -> 538980.49
C10: Rate to include making light templates, MS support of 35mmx35mmx4mm wherever required for support for the ceiling, extra support for trap doors, services junction etc
C11: The rates to be inclusive of cove,grooves,offsets etc
A13: 2 | B13: FC 02 | C13: GI Metal Sheet with Grid and Powder Coated
C15: Providing and fixing Metal open cell ceiling system grid size of 150x150mm as per the architects drawings and manufacturers recommendation with invisible joints with grid like open cell design leaving open spaces between them. The rate shall include main and cross bars, integral hooks, sliding clips suspension rods etc all as per the manufacturers recommendation. | D15: Sqm | E15: 677.9535 | F15: 3567 | G15: =F15*E15 -> 2418260.1
A17: 3 | B17: FC 03 | C17: Moisture resistant Gyp Board False Ceiling
C19: Providing & fixing False ceiling with 12.5 mm moisture resistant gypsum board False ceiling , cut to all shapes & size and in the required grid pattern supported on Powder coated aluminium frame work of approved make consisting of wall angles of section, bulbed Tees, main Tees, cross tees as per the detailed drawings, including providing & fixing MS tab hangers, 6 mm dia MS standard suspenders of required height and providing necessary opening & additional frame work required for light & AC fittings including provision for upturn as pelmets at ends along walls for return air in the false ceiling if required and painting the steel work with one coat of red oxide zinc chromate primer etc., complete all as per specification. Rate to include the provision for Trap doors ,drilling/cutting /providing holes for electrical fixtures /services and finishing the same . | D19: Sqm | E19: 81.3645 | F19: 1413 | G19: =F19*E19 -> 114968.04
A21: 4 | B21: FC 04 | C21: PVC Trap Doors
C23: Providing and fixing trap doors for access to the areas above false ceiling. The trap door shall have an external frame on which the shutter is hinged. The shutter shall be moulded in level with the false ceiling forming a groove all around. Sufficient number of hinges and locks shall be provided to avoid sagging of the shutter. Key also shall be supplied. No extra rate shall be provided for suspenders or frame works alround for linking the trap door to gypboard false ceiling. Refer Architecural drawing for details and manufacturers recommendation. | D23: No | E23: 7 | F23: 6334 | G23: =F23*E23 -> 44338
C24: The vendor to ensure the trap doors should not bend or sag after installtion.
A26: 5 | B26: PNL 01 | C26: Wall Panelling
C28: Providing and fixing moisture-resistant calcium silicate board wall panelling using 8 mm / 10 mm / 12 mm thick boards (as specified), fixed on GI metal framing system (floor channel, vertical studs at 600 mm c/c, top track), including corrosion-resistant screws, jointing tape, joint compound, edge finishing, and preparing the surface ready for painting. Installation to include all materials, labour, scaffolding, consumables, and accessories as per manufacturer’s recommendations. Hilux / Everest / Ramco / Equivalen | D28: Sqm | E28: 200 | F28: 1479 | G28: =F28*E28 -> 295800
F29: 0
B30: PNL 02 | C30: Providing and fixing moisture-resistant gypsum board wall panelling using 12.5 mm thick MR gypsum boards fixed on GI metal framing system (floor channel, vertical studs at 600 mm c/c, top track), including necessary screws, jointing tape, joint compound (3-coat), finishing smooth, and ready for painting. All materials, labour, tools, accessories, and complete installation as per manufacturer’s specifications Gyproc / USG Boral / Equivalent | D30: Sqm | E30: 200 | F30: 1218 | G30: =F30*E30 -> 243600
C34: SUB TOTAL ( F )- FALSE CEILING WORKS | G34: =SUM(G9:G33) -> 3655946.7

Sheet FLR - BOQ
C2: BILL OF QUANTITIES
A3: S.no | B3: Item No | C3: Description | D3: Unit | E3: Qty | F3: Rate | G3: Amount
A5: G | B5: FLR | C5: Flooring Works
C6: Notes: a) All flooring to be protected by 5mm thick floor protector sheet (bubble sheet), (make: Supreme). Flooring to be covered over in finished condition and after uncovering to be delivered in a finished condition free of scratches, lines and any other deformities etc. b) The contractor shall procure mortar, adhesive, grout etc. of approved quality design and standard and he will not change source of supply without written permission from PM and with revised samples being approved. c) Contractor shall prepare and install mockups for floor and wall as per drawings. Mockups may be part of completed work if undistributed. Nothing extra shall be paid on this account. d) Joint patterns to be followed. No extra cuts for variable joint patterns, shall be paid for wastage. e) Skirtings to have profiled edges as per PM's instructions. No extra cost to be paid for plaster chipping, required to adjust skirtings levels. However, cost of mouldings to be indicated separately, so as to deduct cost towards the same, incase profiling is avoided. f) The contractor shall be responsible for protection of his own work and the work of other trades during the progress and till handover to the Employer. All flooring to be protected by 5mm thick floor protector sheet (bubble sheet), (make: Supreme) during construction and polished after laying. Flooring to be covered over in finished condition free of scratches and cracks etc. Cost of 5mm thick floor protector sheet (bubble sheet), (make: Supreme) to be part of quoted rates. g) The rate shall include coving if shown in the drawing. Mode of Measurement: 225mm and below to be paid in Rmt and above 225mm to be paid in Sqm. Finished area shall be measured for payment.
A8: 1 | B8: FLR 01 | C8: Screed
C9: Providing and laying to required slope line Cement screed concrete(smooth finish) flooring of average 30 to 40 mm thick in cement concrete 1:2:4, M15 grade,using 12mm and down graded granite aggregate laid in alternative panels not exceeding 2.5 Sq.m in area laid to proper level, slope , making provision for earth pits, floor conduits etc and finishing, including cleaning of base, curing by ponding water, necessary shuttering with all leads and lifts complete. Top should be finished with power trowel to required finish / as instructed by the Engineer .
C10: The rate should be inclusive of necessary base cleaning,chipping of loose mortar. | D10: Sqm | E10: QRO
C11: Rate quoted shall include for chipping for the conduits/ drain pipes etc and removal of debris from the working area , including carting away from the site, as desired and making good (in perfect condition). On inserting the services, the balance portion to be neatly plastered of mix 1:3 , in proper line and level with the PCC floor
A14: 2 | B14: FLR 02 | C14: 40mm thick Pre Polished KOTA Stone Flooring
C16: Providing & laying 40mm thick Pre-polished Kota stone flooring of approved shade and quality, set on 20-25mm thk cement mortor 1:4, including machine cutting, laying without any surface level mismatch , polymer grout, oxalic acid washing,covering with 50mm thick POP& plastic sheet for the same, making antiskid grooves in steps if any & cleaning at the time when instructed, rectification for damages etc., complete including all leads & lifts at all levels as directed by Engineer Incharge. Care to be taken to see that the laying is done with slabs of matching shades. Extra care to be taken while laying the stones in the areas with borders if any of different materials.The rate to include the cost of buffing and final cleaning.Rate shall include providing coving as per the details in the drawing | D16: Sqm | E16: 928.095 | F16: 1592 | G16: =F16*E16 -> 1477527.2
C17: Any unevenness or undulations/scratches/cutting , re-polishing shall have to be done to make the surface even to the satisfaction of the engineer incharge.
C18: Basic rate of the slab : Rs.80/- per sft
A20: 3 | B20: FLR 03 | C20: 20mm thick Pre Polished KOTA Stone Flooring
C22: Providing & laying 20mm thick Pre-polished Kota stone flooring of approved shade and quality, set on 20-25mm thk cement mortor 1:4, including machine cutting, laying without any surface level mismatch , polymer grout, oxalic acid washing,covering with 50mm thick POP& plastic sheet for the same, making antiskid grooves in steps if any & cleaning at the time when instructed, rectification for damages etc., complete including all leads & lifts at all levels as directed by Engineer Incharge. Care to be taken to see that the laying is done with slabs of matching shades. Extra care to be taken while laying the stones in the areas with borders if any of different materials.The rate to include the cost of buffing and final cleaning. Rate shall include providing coving as per the details in the drawing | D22: Sqm | E22: 124.2675 | F22: 1592 | G22: =F22*E22 -> 197833.86
C23: Any unevenness or undulations/scratches/cutting , re-polishing shall have to be done to make the surface even to the satisfaction of the engineer incharge.
C24: Basic rate of the slab : Rs.60/- per sft
A26: 4 | B26: FLR 04 | C26: Vitrified Tile Flooring
C28: Providing and laying Vitrified tile flooring of make & model as approved by the architects ,size 600x600mm , finished to required slope, set on 20mm thick cement mortar in ratio 1:4, polymer grouting of joints , curing, protecting the tiles by covering with 50mm thick POP with polythene cover . The cost shall include providing patterns, borders, inlays , Spacers etc complete with all leads & lifts at all levels and heights including all wastages, and all as per the instructions of Engineer in Charge/Architects. Oxalic acid washing to be done on the tiled areas before handing over. | D28: Sqm | E28: 87.5175 | F28: 1218 | G28: =F28*E28 -> 106596.32
C29: The cost to include making provisions for grating fixing in coordination with the plumbing agency
C30: All junctions of the wall/dadoo and floor to be filled with sealant.
C31: Basic price of the tile Rs.60/- per sft
A33: 5 | B33: FLR 05 | C33: Ceramic Tile Flooring
C35: Providing and laying Ceramic tile flooring of make & model as approved by the architects ,size 300x300mm , finished to required slope, set on 20mm thick cement mortar in ratio 1:4, polymer grouting of joints , curing, protecting the tiles by covering with 50mm thick POP with polythene cover . The cost shall include providing patterns, borders, inlays , Spacers etc complete with all leads & lifts at all levels and heights including all wastages, and all as per the instructions of Engineer in Charge/Architects. Oxalic acid washing to be done on the tiled areas before handing over. | D35: Sqm | E35: QRO | F35: 0
C36: The cost to include making provisions for grating fixing in coordination with the plumbing agency
C37: All junctions of the wall/dadoo and floor to be filled with sealant.
C38: Basic price of the tile Rs.50/- per sft
A40: 6 | B40: FLR 05 | C40: PU Finish for flooring
C42: Providing and applying PU (Polyurethane) floor coating system of 1.5 to 2 mm thickness over prepared concrete surface in food processing areas, including all materials, labour, surface preparation, equipment, and consumables complete as per specifications and directions of the Engineer-in-Charge. The system shall comprise surface preparation, Primer application with solvent free epoxy primer, PU base coat, PU top coat, curing and final seamless finishing all as per standard norms and manufacturers recommendation. Shade and colour to match the Architects requirements. | D42: Sqm | E42: 174.1005 | F42: 1740 | G42: =F42*E42 -> 302934.87
A44: 7 | B44: FLR 06 | C44: Paver Blocks for Parking
C46: Providing and laying of 300 x300 x120mm thick in size paver blocks of approved shade, Quality & make, laid over 40mm thick compacted sand bed including edge cutting of pavers as per design and setting with mechanical vibrations including all incidentals, etc.,laying without any surface level mismatch & cleaning at the time when instructed, rectification for damages etc., complete including all leads & lifts at all levels as directed by Engineer In-charge. Care to be taken to see that the laying is done with pavers of matching shades. The rate to include for final cleaning. (Basic Rate - Rs 135/Sft) | D46: Sqm | E46: 100 | F46: 2436 | G46: =F46*E46 -> 243600
A48: 8 | B48: FLR 07 | C48: 19mm thick Sadarhalli Flamed Granite Flooring
C50: Providing & laying 19 to 20mm thick flamed Granite slab flooring of approved quality, set on 20-25mm thk cement mortor 1:4, including machine cutting, laying without any surface level mismatch , polymer grout, covering with 50mm thick POP& plastic sheet for the same, cleaning at the time when instructed, rectification for damages etc., complete including all leads & lifts at all levels as directed by Engineer Incharge. Care to be taken to see that the laying is done with slabs of matching shades. Extra care to be taken while laying the stones in the areas with borders if any of different materials.The rate to include the cost of final cleaning. Basic Price of the slab : Rs.90/sft | D50: Sqm | E50: 57.0381 | F50: 3045 | G50: =F50*E50 -> 173681.01
A52: 8 | B52: FLR 08 | C52: 50mm thick Cement Concrete Flooring
C54: Providing and laying to required slope line Cement screed concrete(smooth finish) flooring of average 50mm thick in cement concrete 1:2:4, M15 grade,using 12mm and down graded granite aggregate laid in alternative panels not exceeding 2.5 Sq.m in area laid to proper level, slope , making provision for earth pits, floor conduits etc and finishing, including cleaning of base, curing by ponding water, necessary shuttering with all leads and lifts complete. Top should be finished with power trowel to required finish / as instructed by the Engineer . | D54: Sqm | E54: 202.8915 | F54: 629 | G54: =F54*E54 -> 127618.75
A56: 9 | B56: SKR 02 | C56: PU finish Skirting
C58: Providing and applying PU (Polyurethane) coating system of 3 mm to 4 mm thickness for skirting 100mm high over prepared surface in food processing areas, including all materials, labour, surface preparation, equipment, and consumables complete as per specifications and directions of the Engineer-in-Charge. The system shall comprise surface preparation, Primer application with solvent free epoxy primer, PU base coat, PU top coat, curing and final seamless finishing all as per standard norms and manufacturers recommendation. Shade and colour to match the Architects requirements. | D58: Rmt | E58: 123.4905 | F58: 575 | G58: =F58*E58 -> 71007.038
A60: 10 | B60: SKR 02 | C60: Vitrified Tile Skirting
C62: Providing and laying 100mm high Vitrified tile Skirting of approved equivalent make & shade as approved by the architects, tiles cut to size. The rate shall include the cost of grouting of joints with Balendura/Laticrete or approved equivalent make to match the colour of the tile, chasing of wall to flush the skirting in line with the wall, fixing with approved adhesives to required thickness, oxalic acid washing etc complete, with all leads & lifts at all levels and heights and all as per the instructions of Engineer in Charge/Architects. Wastages shall not be paid extra. (Basic rate : Rs.60/sft) | D62: Rmt | E62: 32.676 | F62: 292 | G62: =F62*E62 -> 9541.392
A64: 11 | B64: SKR 02a | C64: Ceramic Tile Skirting
C66: Providing and laying 100mm high Ceramic tile Skirting of approved equivalent make & shade as approved by the architects, tiles cut to size. The rate shall include the cost of grouting of joints with Balendura/Laticrete or approved equivalent make to match the colour of the tile, chasing of wall to flush the skirting in line with the wall, fixing with approved adhesives to required thickness, oxalic acid washing etc complete, with all leads & lifts at all levels and heights and all as per the instructions of Engineer in Charge/Architects. Wastages shall not be paid extra. (Basic rate : Rs.50/sft) | D66: Rmt | E66: QRO | F66: 0
...

Sheet JNR-BOQ
C2: BILL OF QUANTITIES
A3: S.no | B3: Item No | C3: Description | D3: Unit | E3: Qty | F3: Rate | G3: Amount
A5: H | B5: FD/WD/UP | C5: DOORS
C6: Notes: Archtects drawings / details supercedes the specifications. Kindly refer the drawings before quoting.
A8: 1 | B8: FD | C8: FIRE DOORS
C9: Providing and fixing of hollow metal fire rated doors as per IS 3614: 2021, for 120min integrity only. Pressed galvanized steel confirming to IS 277 with the following specification.Recommended fire door shall be tested as per IS/ISO 3008 & IS/ ISO 834-1, from Exova/TBW/CBRI approved lab.Labled fire doors shall be with fire rated hardware and vision panel all as a complete assembly. Proper label confirming the type of door and the hourly rating is mandatory.
C10: Door frame shall be single rebate grooved profile of size 100 x 57mm made out of 1.20mm (18gauge) minimum thick galvanized steel sheet. Frames shall be mitered and field assembled with self tabs. Frames to have inbuild grooved sealing system for taking fire rated EPDM seals. All provision should be mortised, drilled and tapped for receiving appropriate hardware. Frames should be provided with back plate bracket and anchor fasteners for installation on a finished plastered masonry wall opening. Frames shall be filled with fire rated puff. | D10: Sqm | F10: QRO
C11: Rate shall include supply and installation of frame, shutter as a complete assembly including glass with tapes, louvers, excluding all hardware, smoke seals
C12: Note : Refer Architects Drawing for the details. The description in the BOQ is in general. Contractors to read the architects drawings / details before quoting
A14: 1 | B14: FD 01 | C14: Double Leaf Fire Rated Door with SS Kick Plates
C16: Ironmongery of approved make:
C17: a) SS ball bearing butt hinges size 102mm x 76mm x 3mm - 4 Nos.
C18: b) SS Door handle 300X15/35MM - 1 Nos.
C19: c) SS Door lock (dual bolt) - 1 Nos.
C20: d) SS auto door closer - 1 Nos.
C21: e) Panic bar - 1 Nos.
C22: f) Vision panel of size 200mm x 300mm with approved fire rated glass with 10mm x 10mm beading - 1 Nos.
C24: D1 - 2.4x2.1 | D24: No | E24: 2 | F24: 73950 | G24: =F24*E24 -> 147900
C25: D3 - 1.8x2.1 | D25: No | E25: QRO | F25: 80388
C26: D4 - 1.5x2.1 | D26: No | E26: QRO | F26: 79901
C27: D7 - 1.5x2.1 | D27: No | E27: QRO | F27: 79901
A29: 2 | B29: FD 02 | C29: Single Leaf Fire Rated Door with SS Kick Plates
C31: Item same as above (A ) but with double leaf with vision panel ( 200x300 in each of the leaves - 4mm thk toughened glass wired fire rated with 10x10mm beading )
C33: D2 - 1.2x2.1 | D33: No | E33: 1 | F33: 40890 | G33: =F33*E33 -> 40890
C34: D5 - 1.2x2.1 | D34: No | E34: QRO | F34: 43848
C35: D6 - 1.3x2.1 | D35: No | E35: QRO | F35: 45310
C36: D8 - 1.3x2.1 | D36: No | E36: QRO | F36: 45310
A39: 3 | B39: UPVC 01 | C39: UPVC Doors
C41: Providing and Fixing UPVC Doors of approved make , type as mentioned in the architects drawings and of multi-chambered uPVC profiles for the frame and shutter, EPDM gaskets, powder-coated zinc alloy hardware (hinges, handles, locks), appropriate uPVC glazing beads, and multi-point locking systems with cylinders etc Complete all as per the manufacturers recommendation. The hinges, hardware and locking systems shall be of zinc alloy powder coated.
C43: D2A - 1.2x2.1 | D43: No | E43: 4 | F43: 23490 | G43: =F43*E43 -> 93960
C44: D9 - 1.2x2.1 - Toilet Main Door | D44: No | E44: 3 | F44: 23490 | G44: =F44*E44 -> 70470
C45: D11- 1.2x2.1 ( Service Door ) | D45: No | E45: 4 | F45: 23490 | G45: =F45*E45 -> 93960
C46: D14-0.85x2.15 ( Build 2 ) | D46: No | E46: 1 | F46: 22620 | G46: =F46*E46 -> 22620
C47: D15-0.9x2.15 ( Build 2) | D47: No | E47: 1 | F47: 22620 | G47: =F47*E47 -> 22620
C48: D16-1.2x2.1 | D48: No | E48: 2 | F48: 23490 | G48: =F48*E48 -> 46980
C49: D17 - .93x2.15 | D49: No | E49: 1 | F49: 23490 | G49: =F49*E49 -> 23490
A51: 4 | B51: UPVC 02 | C51: UPVC Windows
C53: Providing and fixing UPVC Three track Sliding Windows made out of UPVC sections , of approved make and colour as approved by the Architects with UPVC shutters , fitted with 6 mm thk Clear plain glass of Saint Gobain/Modi make and with arrangements like weather strips, clips etc., to make them completely waterproof and free from rattling and all standard accessories like self locking system, handles, hinges, screws, nails,insect mesh,hardware of approved make etc., Water tight joints should be ensured with the masonry/RCC by using Sealants as & where necessary. Item inclusive of all fabrication, transportation, fixing at site inclusive of all scaffolding etc., complete to suit the overall sizes of openings as detailed in drawing and as directed by the Architect / Engineer-in-charge. Note : The bottom section to have drain hole arrangement with proper slope )
C54: A1 - 0.9x1.2m | D54: Sqm | E54: 3.24 | F54: 5655 | G54: =F54*E54 -> 18322.2
A56: 5 | B56: UPVC 03 | C56: Ventilators
...

Sheet FURN
A3: SI NO | B3: DESCRIPTION | D3: UOM | E3: QUANTITY | F3: RATE (INR) | G3: AMOUNT (INR)
A5: J
A7: 1 | B7: Cafetaria Tabls | D7: Nos | E7: 8 | F7: 9250 | G7: =F7*E7 -> 74000
A9: 2 | B9: Café Chairs | D9: Nos | E9: 32 | F9: 2920 | G9: =F9*E9 -> 93440
G10: =E10*F10 -> 0
B11: Total Basic Value of Furniture | G11: =SUM(G6:G10) -> 167440
B13: GRAND TOTAL | G13: =SUM(G11:G12) -> 167440

Sheet Structural Summary
A1: STRUCTURAL WORKS SUMMARY
A2: S.no | B2: Description | C2: Amount
A4: A | B4: FRONT AREA - LOADING & UNLOADING BAY | C4: =Structural!M37 -> 1563507.9
A6: B | B6: FRONT AREA - Storage area | C6: =Structural!M59 -> 348423.2
A8: C | B8: DISPATCH BAY | C8: =Structural!M92 -> 1013672.9
A10: D | B10: UG Sump | C10: =Structural!M104 -> 1186108.1
A12: E | B12: . STP | C12: =Structural!M116 -> 2195498.5
A14: F | B14: DG yard | C14: =Structural!M125 -> 122973.79
A16: G | B16: PUMP ROOM | C16: =Structural!M134 -> 141037.49
A18: H | B18: HVAC SUPPORT - INTERNAL AREA | C18: =Structural!M144 -> 1014010.4
A20: I | B20: Overall New footings & pedestals | C20: =Structural!M152 -> 147030.92
B22: TOTAL | C22: =SUM(C4:C20) -> 7732263.2

Sheet Structural
A1: STRUCTURAL WORKS
A5: a). FRONT AREA - LOADING & UNLOADING BAY
A6: S.I No. | B6: items | D6: Nos. | E6: Length | F6: Breadth | G6: Depth | H6: weight/density | I6: Quantity | K6: unit | L6: Rate | M6: Amt
B7: Structural Steel Fabricating, supplying and erecting M.S.tubular Sections of span upto 10m. . The members is anchored in RCC column or Blocks by using M.S. anchor bolts with the base plate and shoe plate.The work includes cutting, straightening, placing in position of M.S angle and wleding wherever necessary, and applying one coat of red oxide primer coat to all themembers including cost of all materials, labour charges, and hire charges of machineries for cutting, welding, grinding and erection equipments, with all lead and lift, transportation, etc., complete as per specification.
A8: 1 | B8: Columns- RHS(300x200x6) | D8: 2 | G8: 3.6 | H8: 45.24 | I8: =+PRODUCT(D8,E8,F8,G8,H8) -> 325.728 | K8: Kgs | L8: 107 | M8: =L8*I8 -> 34852.896
A9: =A8+1 -> 2 | B9: Columns- RHS(300x200x6) | D9: 9 | G9: 4.5 | H9: 45.24 | I9: =+PRODUCT(D9,E9,F9,G9,H9) -> 1832.22 | K9: Kgs | L9: 107 | M9: =L9*I9 -> 196047.54
A10: =A9+1 -> 3 | B10: Endplates | D10: =(D9+D8)*2 -> 22 | E10: 0.4 | F10: 0.5 | G10: 0.012 | H10: 7850 | I10: =+PRODUCT(D10,E10,F10,G10,H10) -> 414.48 | K10: Kgs | L10: 107 | M10: =L10*I10 -> 44349.36
A11: =A10+1 -> 4 | B11: Beams -RHS(300x200x6)(Roof) | D11: 1 | E11: 92 | H11: 45.24 | I11: =+PRODUCT(D11,E11,F11,G11,H11) -> 4162.08 | K11: Kgs | L11: 107 | M11: =L11*I11 -> 445342.56
A12: =A11+1 -> 5 | B12: Beams -RHS(60x40x2.6)(Roof) | D12: 1 | E12: 49 | H12: 3.73 | I12: =+PRODUCT(D12,E12,F12,G12,H12) -> 182.77 | K12: Kgs | L12: 107 | M12: =L12*I12 -> 19556.39
A13: =A12+1 -> 6 | B13: Beams -RHS(200x100x6.0)(Platform) | D13: 1 | E13: 57.2 | H13: 26.4 | I13: =+PRODUCT(D13,E13,F13,G13,H13) -> 1510.08 | K13: Kgs | L13: 107 | M13: =L13*I13 -> 161578.56
A14: =A13+1 -> 7 | B14: Beams -RHS(200x100x6.0)(Platform) | D14: 1 | E14: 36 | H14: 26.4 | I14: =+PRODUCT(D14,E14,F14,G14,H14) -> 950.4 | K14: Kgs | L14: 107 | M14: =L14*I14 -> 101692.8
A15: =A14+1 -> 8 | B15: Beams -RHS(80x40x4.0)(Platform) | D15: 1 | E15: 83.6 | H15: 6.71 | I15: =+PRODUCT(D15,E15,F15,G15,H15) -> 560.956 | K15: Kgs | L15: 107 | M15: =L15*I15 -> 60022.292
A16: =A15+1 -> 9 | B16: Connections | I16: =+(SUM(I8:I15)*0.05) -> 496.9357 | K16: Kgs | L16: 107 | M16: =L16*I16 -> 53172.12
B17: Concrete for footings and pedestals (M25) KSRB 4.2.1 : Providing and laying in position reinforced cement concrete of Design mix M25 with OPC cement @ 340kgs, with 20mm and down size graded granite metal coarse aggregates @0.70 cum and fine aggregtes @ 0.47cum, with super plasticisers @ 3 liters confirming to is 9103-1999 reafirmed-2008 at machine mixed, concrete laid in layers not exceeding 15 cms thick, vibrated for all works in foundation for footings, pedastals, retaining walls, return walls, walls (any thickness) including attached pilasters, columnspillars, posts, struts, buttresses, bed blocks, anchor blocks & plinths etc., including cost of all materials, labour, HOM of machinery, curing, complete but excluding cost of reinforcement as per specifications. Specification No. KBS 4.1, 4.6 | L17: 0 | M17: =L17*I17 -> 0
A18: =A16+1 -> 10 | B18: Foundation | D18: =D9+D8 -> 11 | E18: 0.65 | F18: 0.75 | G18: 1.05 | I18: =+PRODUCT(D18,E18,F18,G18,H18) -> 5.630625 | K18: Cum | L18: 14355 | M18: =L18*I18 -> 80827.622
A19: =A18+1 -> 11 | B19: Pedestals | D19: =D18 -> 11 | E19: 0.55 | F19: 0.65 | G19: 1 | I19: =+PRODUCT(D19,E19,F19,G19,H19) -> 3.9325 | K19: Cum | L19: 14355 | M19: =L19*I19 -> 56451.038
B20: Reinforcing Steel KSRB 4.9.2 : Providing TMT steel reinforcement for R C C work including straightening, cutting, bending, hooking, placing in position, lapping and / or welding wherever required, tying with binding wire and anchoring to the adjoining members wherever necessary complete as per design ( laps, hooks and wastage shall not be measured and paid ) cost of materials, labour, HOM of machinery complete as per specifications. TMT bars Fe 500 | L20: 0 | M20: =L20*I20 -> 0
A21: =A19+1 -> 12 | B21: reinforcements | I21: =+(I18+I19)*75 -> 717.23438 | K21: Kgs | L21: 107 | M21: =L21*I21 -> 76744.078
B22: GI sheet Providing & fixing corrugated G.S. sheet roofing including vertical/curved surface fixed with polymer coated J or L hooks, bolts and nuts 8 mm diameter with bitumen and G.I. limpet washers or with G.I. limpet washers filled with white lead, including a coat of approved steel primer and two coats of approved paint on overlapping of sheets complete as per design drawings (up to any pitch in horizontal/ vertical or curved surfaces), excluding the cost of purlins, rafters and trusses and including cutting to size and shape wherever required as per the direction of Engineer in charge. | L22: 0 | M22: =L22*I22 -> 0
A23: =A21+1 -> 13 | B23: G.I Sheet area | D23: 1 | E23: 82.93 | I23: =E23*D23 -> 82.93 | K23: Sqm | L23: 1127 | M23: =L23*I23 -> 93462.11
B24: SSM KSRB 5.2-1 : Providing and constructing granite / trap / basalt size stone masonry in foundation with mud mortar, stone hammerd dressed in courses not less than 20 cms high, bond stones at two m. apart in each course including cost of materials, labour, curing complete as per specifications. KBS 5.1.12 | L24: 0 | M24: =L24*I24 -> 0
A25: =A23+1 -> 14 | B25: SSM For Loading Stage | D25: 1 | E25: 12.525 | F25: 0.6 | G25: 0.3 | I25: =+PRODUCT(D25,E25,F25,G25,H25) -> 2.2545 | K25: Cum | L25: 10740 | M25: =L25*I25 -> 24213.33
B26: 2nd coarse | D26: 1 | E26: =E25 -> 12.525 | F26: 0.45 | G26: 0.8 | I26: =+PRODUCT(D26,E26,F26,G26,H26) -> 4.509 | K26: Cum | L26: 10740 | M26: =L26*I26 -> 48426.66
B27: Plain Cement Concrete KSRB-4-1.3 : Providing and laying in position plain cement concrete of mix 1:4:8 with OPC cement @ 180kgs, with 40mm and down size graded granite metal coarse aggregates @ 0.85cum and fine aggregates @ 0.57cum machine mixed, concrete laid in layers not exceeding 15 cms. thick, well compacted, in foundation including cost all materials, labour, HOM of machinery, curing complete as per specifications. | L27: 0 | M27: =L27*I27 -> 0
A28: =A25+1 -> 15 | B28: PCC | L28: 0 | M28: =L28*I28 -> 0
B29: under SSM | D29: 1 | E29: =E26 -> 12.525 | F29: 0.8 | G29: 0.15 | I29: =+PRODUCT(D29,E29,F29,G29,H29) -> 1.503 | K29: Cum | L29: 9135 | M29: =L29*I29 -> 13729.905
B30: under pedestals | D30: =D18 -> 11 | E30: =E18+0.3 -> 0.95 | F30: =F18+0.3 -> 1.05 | G30: 0.15 | I30: =+PRODUCT(D30,E30,F30,G30,H30) -> 1.645875 | K30: Cum | L30: 9135 | M30: =L30*I30 -> 15035.068
B31: Excavation Earth work excavation for foundation of structures by mechanical means as per drawing and technical specification, including setting out, construction of shoring and bracing, removal of stumps and other deleterious matter, dressing of sides and bottom, backfilling the excavation earth to the extent required and utilising / transporting the remaining earth locally upto 1.00km lead. (Depth upto 3.00 Mts) -In all types of soil | L31: 0 | M31: =L31*I31 -> 0
A32: =A28+1 -> 16 | B32: Excavation | L32: 0 | M32: =L32*I32 -> 0
B33: under SSM | D33: 1 | E33: =E29 -> 12.525 | F33: 0.6 | G33: 1 | I33: =+PRODUCT(D33,E33,F33,G33,H33) -> 7.515 | K33: Cum | L33: 1730 | M33: =L33*I33 -> 13000.95
B34: under pedestals | D34: =D19 -> 11 | E34: =E19 -> 0.55 | F34: =F19 -> 0.65 | G34: =G19 -> 1 | I34: =+PRODUCT(D34,E34,F34,G34,H34) -> 3.9325 | K34: Cum | L34: 1730 | M34: =L34*I34 -> 6803.225
B35: GI GUTTER Providing & fixing corrugated G.S. sheet roofing including vertical/curved surface fixed with polymer coated J or L hooks, bolts and nuts 8 mm diameter with bitumen and G.I. limpet washers or with G.I. limpet washers filled with white lead, including a coat of approved steel primer and two coats of approved paint on overlapping of sheets complete as per design drawings (up to any pitch in horizontal/ vertical or curved surfaces), excluding the cost of purlins, rafters and trusses and including cutting to size and shape wherever required as per the direction of Engineer in charge. | L35: 0 | M35: =L35*I35 -> 0
A36: =A32+1 -> 17 | B36: GI Gutter | D36: 1 | E36: 9.25 | F36: 1.25 | I36: =+PRODUCT(D36,E36,F36,G36,H36) -> 11.5625 | K36: Sqm | L36: 1574 | M36: =L36*I36 -> 18199.375
L37: 0 | M37: =SUM(M8:M36) -> 1563507.9
A38: b). FRONT AREA - Storage area | L38: 0
B39: Structural Steel Fabricating, supplying and erecting M.S.tubular Sections of span upto 10m. . The members is anchored in RCC column or Blocks by using M.S. anchor bolts with the base plate and shoe plate.The work includes cutting, straightening, placing in position of M.S angle and wleding wherever necessary, and applying one coat of red oxide primer coat to all themembers including cost of all materials, labour charges, and hire charges of machineries for cutting, welding, grinding and erection equipments, with all lead and lift, transportation, etc., complete as per specification. | L39: 0
A40: 1 | B40: Columns- RHS(172x92x4.8) | D40: 5 | G40: 4.5 | H40: 18.71 | I40: =+PRODUCT(D40,E40,F40,G40,H40) -> 420.975 | K40: Kgs | L40: 107 | M40: =L40*I40 -> 45044.325
A41: =A40+1 -> 2 | B41: Endplates | D41: =(D40)*2 -> 10 | E41: 0.3 | F41: 0.4 | G41: 0.012 | H41: 7850 | I41: =+PRODUCT(D41,E41,F41,G41,H41) -> 113.04 | K41: Kgs | L41: 107 | M41: =L41*I41 -> 12095.28
A42: =A41+1 -> 3 | B42: Beams -RHS(145x82x4.8)(Roof) | D42: 1 | E42: 27 | H42: 15.92 | I42: =+PRODUCT(D42,E42,F42,G42,H42) -> 429.84 | K42: Kgs | L42: 107 | M42: =L42*I42 -> 45992.88
A43: =A42+1 -> 4 | B43: Beams -RHS(60x40x2.6)(Roof) | D43: 1 | E43: 18 | H43: 3.73 | I43: =+PRODUCT(D43,E43,F43,G43,H43) -> 67.14 | K43: Kgs | L43: 107 | M43: =L43*I43 -> 7183.98
...

Sheet PHE R1 SUMMARY
A2: Summary
A4: Part | B4: Description | C4: Supply Amount in INR | D4: Install Amount in INR | E4: Total Amount in INR
A7: I | B7: SANITARY & CP FIXTURE | C7: ='PHE WORKS-R1'!G18 -> 333772 | D7: ='PHE WORKS-R1'!H18 -> 74708 | E7: =D7+C7 -> 408480
A9: II | B9: SOIL, WASTE AND VENT & RAIN WATER SYSTEM - (INTERNAL & TERRACE) | C9: ='PHE WORKS-R1'!G56 -> 466276 | D9: ='PHE WORKS-R1'!H56 -> 188238 | E9: =D9+C9 -> 654514
A11: III | B11: WATER SUPPLY SYSTEM - INTERNAL & EXTERNAL | C11: ='PHE WORKS-R1'!G112 -> 305172 | D11: ='PHE WORKS-R1'!H112 -> 84456 | E11: =D11+C11 -> 389628
A13: IV | B13: EXTERNAL WATER SUPPLY SYSTEM | C13: ='PHE WORKS-R1'!G140 -> 401073 | D13: ='PHE WORKS-R1'!H140 -> 93636 | E13: =D13+C13 -> 494709
A15: V | B15: EXTERNAL RAIN/STORM WATER MANAGEMENT( As per Client confirmation the existing system to be utilised) | C15: ='PHE WORKS-R1'!G160 -> 0 | D15: ='PHE WORKS-R1'!H160 -> 0 | E15: =D15+C15 -> 0
A17: VI | B17: EXTERNAL SEWERAGE SYSTEM | C17: ='PHE WORKS-R1'!G179 -> 1019932 | D17: ='PHE WORKS-R1'!H179 -> 352014 | E17: =D17+C17 -> 1371946
A19: VII | B19: PUMPS & CONTROL PANEL | C19: ='PHE WORKS-R1'!G224 -> 1575488 | D19: ='PHE WORKS-R1'!H224 -> 221192 | E19: =D19+C19 -> 1796680
B21: GRAND TOTAL | C21: =SUM(C6:C20) -> 4101713 | D21: =SUM(D6:D20) -> 1014244 | E21: =SUM(E6:E20) -> 5115957

Sheet PHE WORKS-R1
A2: SL NO | B2: DESCRIPTION | C2: Unit | D2: Qty | E2: Supply Rate in INR | F2: Install Rate in INR | G2: Supply Amount in INR | H2: Install Amount in INR | I2: C&W REVIEW / COMMENTS
A5: I | B5: SANITARY & CP FIXTURE
A6: 1 | B6: Providing, fixing, testing and commissioning of white vitreous China wall mounting type European water closet with Concealed Cistern with Suitable C.I. chair or other hanging arrangements, WC connection set dia 90 mm complete of approved make including Bakelite seat & cover with C.P. hinges & rubber buffers, C.P. bolts, nut, necessary adaptors etc, 1 nos angle valve & connection pipes as required Including cutting & making good the walls & floors wherever required . (EWC 18131IN-S-0 Crystal Model - Make - parryware or equivalent) | C6: Nos | D6: 4 | E6: 17052 | F6: 2436 | G6: =E6*D6 -> 68208 | H6: =F6*D6 -> 9744
E7: 0 | F7: 0
A8: =A6+1 -> 2 | B8: Providing ,fixing , testing and commissioning of 15mm CP health faucet of approved make with 1 no angle valve with necessary CP flexible hose 750 mm long nozzle,CP wall flange complete. (Make : parryware T9961A1 Crust with Hose & Hook or equivalent) | C8: Nos | D8: 4 | E8: 1315 | F8: 146 | G8: =E8*D8 -> 5260 | H8: =F8*D8 -> 584
E9: 0 | F9: 0
A10: =A8+1 -> 3 | B10: Providing, fixing, testing and commissioning of white vitreous china rectangular/oval/ round type wash basin including single lever basin tap, 1 nos angle valve, waste coupling, bottle trap, CI / Polymer brackets duly painted, CP connection pipes, cutting and making good the walls floors wherever required. (C0407 (550 x 445 x 200mm) : Make : Parryware or equivalent) | C10: Nos | D10: 6 | E10: 12180 | F10: 2436 | G10: =E10*D10 -> 73080 | H10: =F10*D10 -> 14616
E11: 0 | F11: 0
A12: =A10+1 -> 4 | B12: Supply, Installing, testing and commissioning of GLAZED FLAT BACK URINAL WITH SERSOR BASED operated and has a provison of converter for the urinal sensor from DC to AC” with 6V adaptor. 32mm dia CP waste coupling with dome type grating, 32mm dia CP bottle trap/built in integral trap with extension pipe, urinal spreader, SS bolts and nuts to fix the urinal with chasing of wall and repacking the same with necssary supports etc. complete, the rate quote shall also includes provision of conduit to be made for laying the conduit inside wall sensor operated with AC, which include necessary white cement to pack the Conduit/fixture after installation and related accessories as per requirement . Vendor to check the model and make before fixing the inlet and outlet for urinal. . (Make : parryware, Model : C0501 (270 x 360 x 440mm) flat back or equivalent) | C12: Nos | D12: 2 | E12: 17052 | F12: 3410 | G12: =E12*D12 -> 34104 | H12: =F12*D12 -> 6820
E13: 0 | F13: 0
A14: =A12+1 -> 5 | B14: Providing ,fixing , testing and commissioning 15 mm dia. CP angle Pressure rating minimum of 5 bar the equipment should be provided. (Angle Cock -Make: Jaguar Model : FLR-5053 or equivalent) | C14: Nos | D14: 176 | E14: 870 | F14: 244 | G14: =E14*D14 -> 153120 | H14: =F14*D14 -> 42944
E15: 0 | F15: 0
A16: =A14+1 -> 6 | B16: Providing ,fixing , testing and commissioning of 15mm CP bib-cock with CP flanges including necessary fixing materials etc., complete. | C16: Nos | D16: RO | E16: 0 | F16: 0
B18: TOTAL - I | G18: =SUM(G6:G17) -> 333772 | H18: =SUM(H6:H17) -> 74708
A20: II | B20: SOIL, WASTE AND VENT & RAIN WATER SYSTEM - (INTERNAL & TERRACE)
A21: 1 | B21: Supplying, laying, jointing, testing and commission-ing approved make UPVC pipes 6 Kg/cm2 with solvent cement joints confirming to IS 4985 for SINK outlets and Antisyphonage Pipes.The quoted rate shall include necessary chasing in walls making good the same in C.M. 1:4, necessary fittings viz.,elbows, tees etc., with G.I clamps. Anchor fasteners, Grip bolts, nuts and bolts, etc,complete.
B22: a) 40 mm Outer dia (Wash basin) | C22: Rmt | D22: 20 | E22: 292 | F22: 97 | G22: =E22*D22 -> 5840 | H22: =F22*D22 -> 1940
B23: b) 50 mm Outer dia (Kitchen sink) | C23: Rmt | D23: 60 | E23: 341 | F23: 97 | G23: =E23*D23 -> 20460 | H23: =F23*D23 -> 5820
E24: 0 | F24: 0
A25: 2 | B25: Supplying, jointing, testing & Commissioning of approved make UPVC pipe SWR Type " B " confirming to IS 13592 with rubber ring/solvent joints for soil waste lines confirming to IS 5382.The quoted rate shall include necessary bends,shoes,supporting, M.S Brackets, G.I.Clamps, anchor fasteners, Grip bolts, nuts and bolts, GI suspenders, etc., complete | E25: 0 | F25: 0
B26: INTERNAL : | E26: 0 | F26: 0
B27: a) 110 mm O.D | C27: Rmt | D27: 20 | E27: 487 | F27: 97 | G27: =E27*D27 -> 9740 | H27: =F27*D27 -> 1940
B28: b) 75 mm O.D | C28: Rmt | D28: 30 | E28: 468 | F28: 97 | G28: =E28*D28 -> 14040 | H28: =F28*D28 -> 2910
B29: c) 160 mm O.D | C29: Rmt | D29: 80 | E29: 682 | F29: 97 | G29: =E29*D29 -> 54560 | H29: =F29*D29 -> 7760
B30: c) 200 mm O.D | C30: Rmt | D30: 90 | E30: 780 | F30: 97 | G30: =E30*D30 -> 70200 | H30: =F30*D30 -> 8730
B31: d) 160 mm O.D | C31: Rmt | D31: 200 | E31: 682 | F31: 97 | G31: =E31*D31 -> 136400 | H31: =F31*D31 -> 19400
B32: e) 110 mm O.D | C32: Rmt | D32: 120 | E32: 487 | F32: 97 | G32: =E32*D32 -> 58440 | H32: =F32*D32 -> 11640
B33: f) 75 mm O.D | C33: Rmt | D33: 40 | E33: 468 | F33: 97 | G33: =E33*D33 -> 18720 | H33: =F33*D33 -> 3880
E34: 0 | F34: 0
E35: 0 | F35: 0
A36: 4 | B36: Supplying, jointing, testing & Commissioning of approved make UPVC pipe SWR Type " B " confirming to IS 13592 with rubber ring/solvent joints for rain water disposal confirming to IS 5382.The quoted rate shall include necessary bends,shoes,supporting, M.S Brackets, G.I.Clamps, anchor fasteners, Grip bolts, nuts and bolts, GI suspenders, etc., complete. | E36: 0 | F36: 0
B37: Rain water pipes | E37: 0 | F37: 0
B38: 75 mm O.D (Terrace head room) | C38: Rmt | D38: 5 | E38: 468 | F38: 97 | G38: =E38*D38 -> 2340 | H38: =F38*D38 -> 485
B39: 110 mm O.D | C39: Rmt | D39: RO | E39: 0 | F39: 0
E40: 0 | F40: 0
A41: 6 | B41: Supplying and fixing of approved make PVC RAIN WATER COLLECTION KHURRA made out of UPVC with flange with leaf trap grating complete. | E41: 0 | F41: 0
B42: Side Type Through : | E42: 0 | F42: 0
B43: 110mm dia | C43: Nos. | D43: RO | E43: 0 | F43: 0
B44: Dome Type Through : | E44: 0 | F44: 0
B45: 75mm dia | C45: Nos. | D45: 1 | E45: 2436 | F45: 1462 | G45: =E45*D45 -> 2436 | H45: =F45*D45 -> 1462
...
