Workbook
Name \a: #REF!
Name \a: #REF!
Name CABLE: #REF!
Name CABLE: #REF!

Sheet Consolidated Summary
A1: Consolidated Summary
A3: Part | B3: Description | C3: Supply Amount in INR | D3: Install Amount in INR | E3: Total Amount in INR
A5: 1 | B5: Electrical Package | C5: ='Electrical Summary'!C33 -> 10654432 | D5: ='Electrical Summary'!D33 -> 1975942 | E5: =D5+C5 -> 12630374
A7: 2 | B7: Fire Package | C7: ='FIRE -SUMMARY'!C22 -> 2872072 | D7: ='FIRE -SUMMARY'!D22 -> 587790 | E7: =D7+C7 -> 3459862
B8: Grand Total (Excluding taxes) | C8: =SUM(C5+C7) -> 13526504 | D8: =SUM(D5+D7) -> 2563732 | E8: =SUM(E5+E7) -> 16090236

Sheet Electrical Summary
A1: Subject | B1: : Electrial BOQ - Summary
A3: Summary
A5: Part | B5: Description | C5: Supply Amount in INR | D5: Install Amount in INR | E5: Total Amount in INR
A7: 1 | B7: LT PANELS | C7: ='Electrical BOQ'!G98 -> 2834904 | D7: ='Electrical BOQ'!H98 -> 334506 | E7: =D7+C7 -> 3169410
A9: 2 | B9: LT CABLES | C9: ='Electrical BOQ'!G214 -> 2703414 | D9: ='Electrical BOQ'!H214 -> 477281 | E9: =D9+C9 -> 3180695
A11: 3 | B11: MCB DISTRIBUTION BOARDS | C11: ='Electrical BOQ'!G313 -> 140089 | D11: ='Electrical BOQ'!H313 -> 14630 | E11: =D11+C11 -> 154719
A13: 4 | B13: CIRCUITMAINS / SUBMAINS | C13: ='Electrical BOQ'!G341 -> 1395750 | D13: ='Electrical BOQ'!H341 -> 245100 | E13: =D13+C13 -> 1640850
A15: 5 | B15: POWER RECEPTACLES | C15: ='Electrical BOQ'!G386 -> 555371 | D15: ='Electrical BOQ'!H386 -> 168008 | E15: =D15+C15 -> 723379
A17: 6 | B17: ='Electrical BOQ'!B388 -> POINT WIRING | C17: ='Electrical BOQ'!G408 -> 404708 | D17: ='Electrical BOQ'!H408 -> 86864 | E17: =D17+C17 -> 491572
A19: 7 | B19: LIGHT FIXTURE | C19: ='Electrical BOQ'!G467 -> 732140 | D19: ='Electrical BOQ'!H467 -> 129343 | E19: =D19+C19 -> 861483
A21: 8 | B21: CABLE TRAY | C21: ='Electrical BOQ'!G497 -> 422025 | D21: ='Electrical BOQ'!H497 -> 113420 | E21: =D21+C21 -> 535445
A23: 9 | B23: RACEWAYS | C23: ='Electrical BOQ'!G598 -> 440490 | D23: ='Electrical BOQ'!H598 -> 163790 | E23: =D23+C23 -> 604280
A25: 10 | B25: EARTHING | C25: ='Electrical BOQ'!G648 -> 498564 | D25: ='Electrical BOQ'!H648 -> 106440 | E25: =D25+C25 -> 605004
A27: 10 | B27: BURIED PIPES & IC | C27: ='Electrical BOQ'!G687 -> 273055 | D27: ='Electrical BOQ'!H687 -> 59756 | E27: =D27+C27 -> 332811
A29: 11 | B29: MISCELLANEOUS ITEMS | C29: ='Electrical BOQ'!G709 -> 253922 | D29: ='Electrical BOQ'!H709 -> 76804 | E29: =D29+C29 -> 330726
A31: 11 | B31: LPS RELATED WORKS | C31: =' Lighting protection BOQ'!I29 -> 0 | D31: =' Lighting protection BOQ'!J29 -> 0 | E31: =D31+C31 -> 0
B33: TOTAL | C33: =SUM(C7:C32) -> 10654432 | D33: =SUM(D7:D32) -> 1975942 | E33: =SUM(E7:E32) -> 12630374
B35: Assumptions & Exclusions
A36: 1 | B36: Lighting costing can be arrived upon finalization of the fixtures.
A37: =A36+1 -> 2 | B37: The costing includes supply of cables & panels from the LT Kiosk & further down the load.
A38: =A37+1 -> 3 | B38: Earthing cable/strip might be change as per the site condition.
A39: =A38+1 -> 4 | B39: The length of cables might change as per the final location of panels inside the kitchen.
A40: =A39+1 -> 5 | B40: Electrial works considered within property only, charges towards bringing the power to the property is excluded in this BOQ.
A41: =A40+1 -> 6 | B41: The length of cables might change as per the final location of DB's.
A42: =A41+1 -> 7 | B42: All major civil works viz., foundation for DG, Cable Trench / Tunnel works excluded.
A43: =A42+1 -> 8 | B43: Light fixtures quantities & makes will be as per final design.
A44: =A43+1 -> 9 | B44: 325kVA DG set & accessories is not considered as the client will be renting out 325kVA DG set.
A45: =A44+1 -> 10 | B45: Scaffolding to install light fixtures & cabletrays or any service related installation to be provided at site.
A46: =A45+1 -> 11 | B46: Only conduit / raceways are considered for networking. Active components, I/O ports and cables are not considered.
A47: =A46+1 -> 12 | B47: DG & UPS-related works are not included in the BOQ.
A48: =A47+1 -> 13 | B48: We have not considered the conduits for the fire alarm & CCTV cables.
... A50: =A49+1 -> 15 | B50: TNEB service connection charges are not included.
A51: 16 | B51: Contractor to include arrangement of temporary power during construction, preparation of as-built drawings in the scope of work. These will not be paid separately.
A52: 17 | B52: The costs indicated are exclusive of taxes.

Sheet Electrical BOQ
A1: ELECTRICAL BOQ
A3: Sl. No. | B3: DESCRIPTION | C3: Unit | D3: Qty | E3: Supply Rate in INR | F3: Install Rate in INR | G3: Supply Amount in INR | H3: Install Amount in INR
A6: 1 | B6: LT PANELS:
B8: Panels as per technical specifications & schematic diagram.
B9: Supply, Installation, Testing and Commissioning of Indoor type LT Switchboards, Floor mounting type, Bottom/Top entry. Refer enclosed SLD.
B10: Enclosure: Compartmentalized Single front CRGO (Cold rolled grain oriented sheet steel)
B11: Doors:2mm Body:2mm Gland:3mm covers and partitions:1.6mm
B12: IP class:IP52 for Indoor/IP55 with weather proof enclosure for outdoor
B13: Bus bars: Electrolytic grade conductivity as per standard IS 5082
B14: Bus bar Material: As per SLD
B15: Bus bar supports: DMC/FRP/SMC
B16: Bus bar joints: Shrouded/Tinned
B17: Protection releases: As per SLD (Adjustable over current & short circuit unless otherwise specified)
B18: Ics=Icu for all breakers
B19: Utilization category: All MCCB/ACB's shall be Cat: A except ACB's for Ltg & raw power input distribution panel shall be with Cat: B .
... B43: Please refer make of materials tab for further detailing
A46: 1.1 | B46: Fully Automatic DOL/ Star Delta starters with features like Local/Remote, Auto/Manual & programmable timer for auto operation. Start delta starters shall be provided 5.5kW and above rating. The necessary NO NC shall be provided with BMS compatibility. The space provision for VFD with bypass facility shall be provided wherever it is specified as below. For AHU VFD Panels will be installed by Builder. Starter will be used in case of VFD Panel Maintenance/Failure. The AHU panel to be tripped in case of fire, hence necessary contactors for the same to be provided
A48: =A46+0.1 -> 1.2 | B48: 500A FP AERIAL BOARD - 1&2 | C48: No | D48: 2 | E48: 1316520 | F48: 146280 | G48: =E48*D48 -> 2633040 | H48: =F48*D48 -> 292560
E49: 0 | F49: 0 | G49: =E49*D49 -> 0 | H49: =F49*D49 -> 0
A50: =A48+0.1 -> 1.3 | B50: LTCT EB METER - 1 & 2 | C50: No | D50: 2 | E50: 0 | F50: 0 | G50: =E50*D50 -> 0 | H50: =F50*D50 -> 0
B51: LT CT metering provision for energy meter comprising with Floor Mounted, Cubicle Type Dust &Vermin Proof Powder coating construction, 16 SWG CR sheet enclosure with With as per the TNEB Requirement Test block-13 terminal, Three way Gang box (back open ) Flush type SP Switch,CT Coils -3nos testing by TNEB,15A HRC Fuse Unit With 2A Fuse link & Brass & GI Screw,nut ,washer with 500A Al.bus bars with phase / neutral and internal accessories with powder coated enclosurer With complete TNEB Norms. | E51: 0 | F51: 0 | G51: =E51*D51 -> 0 | H51: =F51*D51 -> 0
E52: 0 | F52: 0 | G52: =E52*D52 -> 0 | H52: =F52*D52 -> 0
A53: =A50+0.1 -> 1.4 | B53: FUSE MAIN PANEL - 1 The fuse rating as per the electrical SLD & as per TNEB norms. | C53: No | D53: 1 | E53: 0 | F53: 0 | G53: =E53*D53 -> 0 | H53: =F53*D53 -> 0
E54: 0 | F54: 0 | G54: =E54*D54 -> 0 | H54: =F54*D54 -> 0
A55: =A53+0.1 -> 1.5 | B55: FUSE MAIN PANEL - 2 The fuse rating as per the electrical SLD & as per TNEB norms. | C55: No | D55: 1 | E55: 0 | F55: 0 | G55: =E55*D55 -> 0 | H55: =F55*D55 -> 0
E56: 0 | F56: 0 | G56: =E56*D56 -> 0 | H56: =F56*D56 -> 0
A57: =A55+0.1 -> 1.6 | B57: APFC PANEL - 1 & 2 | C57: No | D57: 2 | E57: 0 | F57: 0 | G57: =E57*D57 -> 0 | H57: =F57*D57 -> 0
E58: 0 | F58: 0 | G58: =E58*D58 -> 0 | H58: =F58*D58 -> 0
A59: =A57+0.1 -> 1.7 | B59: ELECTRICAL PANEL - 1 | C59: No | D59: 1 | E59: 0 | F59: 0 | G59: =E59*D59 -> 0 | H59: =F59*D59 -> 0
E60: 0 | F60: 0 | G60: =E60*D60 -> 0 | H60: =F60*D60 -> 0
A61: =A59+0.1 -> 1.8 | B61: ELECTRICAL PANEL - 2 | C61: No | D61: 1 | E61: 0 | F61: 0 | G61: =E61*D61 -> 0 | H61: =F61*D61 -> 0
E62: 0 | F62: 0 | G62: =E62*D62 -> 0 | H62: =F62*D62 -> 0
A63: =A61+0.1 -> 1.9 | B63: PHE PANEL | C63: No | D63: 1 | E63: 0 | F63: 0 | G63: =E63*D63 -> 0 | H63: =F63*D63 -> 0
E64: 0 | F64: 0 | G64: =E64*D64 -> 0 | H64: =F64*D64 -> 0
A65: 1.1 | B65: DG BREAKER PANEL (OUTDOOR TYPE) | C65: No | D65: 1 | E65: 0 | F65: 0 | G65: =E65*D65 -> 0 | H65: =F65*D65 -> 0
E66: 0 | F66: 0 | G66: =E66*D66 -> 0 | H66: =F66*D66 -> 0
A67: 1.11 | B67: 4P MCB ISOLATOR with enclosures | E67: 0 | F67: 0 | G67: =E67*D67 -> 0 | H67: =F67*D67 -> 0
A68: 1.11.1 | B68: 16A | C68: No | D68: R.O | E68: 0 | F68: 0
A69: 1.11.2 | B69: 20A / 25A | C69: No | D69: R.O | E69: 0 | F69: 0
A70: 1.11.3 | B70: 32A (Kitchen equipments) | C70: No | D70: 10 | E70: 1950 | F70: 488 | G70: =E70*D70 -> 19500 | H70: =F70*D70 -> 4880
...

Sheet  Lighting protection BOQ
A2: Sl. No. | B2: Description | D2: Product Images | E2: Unit | F2: Quantity | G2: Supply Rate in INR | H2: Install Rate in INR | I2: Supply Amount in INR | J2: Install Amount in INR
B3: Air Terminal
A4: 12.1 | B4: Supply of 8 mm Aluminum Round Conductor complete as specified in drawing & Meets the requirements of DIN EN 50164-2 (VDE 0185 part 202) & VDE 0185-305 (IS/IEC 62305) OBO Type No. RD 8/ALU | E4: Mtr | F4: R.O
A5: =A4+0.1 -> 12.2 | B5: Supply of Roof conductor holder for parapet- Polyamide Conductor holder: With M8 female thread or diameter 7mm, M8 Screw to connect the conductor holder.Weather and temperature resistant from -35 to +90 degree Celsius tested. Conductor holder @ 1 meter distance OBO Type No. 177 30 M8(5207460 ) | E5: Nos | F5: R.O
A6: =A5+0.1 -> 12.3 | B6: Polyamide roof cable holder for flat roof: DIN 48829 Form B1. Closed form with bottom. Filling weight 1Kg (frost-resistant concrete). Sleeve from polyethylene, black @ 1 meter distance. OBO Type No. 165 MBG-8-10 ( 5218700 ) | E6: Nos | F6: R.O
A7: =A6+0.1 -> 12.4 | B7: Supply of Roof conductor holder - Stainless steel Conductor holder: With Bottom section and conductor holder stainless steel (V2A)Bottom section with Ø 8.5 mm slot. Conductor holder @ 1 meter distance. OBO Type No. 159 VA-V (5217 07 5 ) | E7: Nos | F7: R.O
A8: =A7+0.1 -> 12.5 | B8: Supply of 1 mtr vertical air terminal with mounting accessories on the flat surface to meet the requirements of IS/IEC 62305. Tested for Electrical , mechanical and chemical as per IEC 62561. Tested for 100kA lightning current. F-FIX JUNIOR 5403308 | E8: Nos | F8: R.O
A9: =A8+0.1 -> 12.6 | B9: 4 Mtr Vertical air terminal with accessories:Providing of Air terminals as per IS-IEC -62305 part-3 Nominal size Ø10/16 mm aluminium rod: 2448801) Suitable for high wind load.Tested as per IEC 62561(1-8) and relevant test report should be submitted. OBO Type No. 101 VL4000 ( 5401995) | E9: Nos | F9: R.O
A10: =A9+0.1 -> 12.7 | B10: Providing of Stand for Fang Fix system 16 kg with base and clamp ,made up of frost resistant concrete OBO type No.F-FIX-S16 I (5450080) | E10: Nos | F10: R.O
A11: =A10+0.1 -> 12.8 | B11: Providing of Stand for Fang Fix system 16 kg with base and clamp ,made up of frost resistant concrete and tested upto 100KA lightning current. Tested as per IEC 62561(1-8) and relevant test report should be submitted for 100kA lightning current testing. OBO type No.F-FIX-16 (5403200) | E11: Nos | F11: R.O
A12: =A11+0.1 -> 12.9 | B12: Supply of Test Joint suitable to connect 8mm round conductor and 30x3 mm GI strip. Fit: Rd 8-10 x FL 30 Mounted with 4 hexagonal bolts M8 x 25 and 4 hexagonal nuts M8. 252 S4 FT 5312302 | E12: Nos | F12: R.O
A13: 12.1 | B13: Providing of expansion piece with connector: For equalising temperature related length changes. Necessary on conductors length over 20 meters. For round conductor Rd 8/ALU. OBO Type No. 172 AR ( 5218 92 6 ) | E13: Nos | F13: R.O
A14: =A13+0.01 -> 12.11 | B14: Connector: For T cross and parallel connectors. Quick installation using hexagonal bolt M10X30 high-grade hot dip galvanised. Conforms to the requirements according to DIN VDE 0185-305 (IS-IEC 62305)(2nos/expansion piece). OBO Type No. 249 8-10 ST ( 5311500 ) | E14: Nos | F14: R.O
B15: Down Conductor System
A16: =A14+0.01 -> 12.12 | B16: Supply of 8 mm Aluminum Round Conductor complete as specified in drawing & Meets the requirements of DIN EN 50164-2 (VDE 0185 part 202) & VDE 0185-305 (IS/IEC 62305) OBO Type No. RD 8/ALU | E16: Mtr | F16: R.O
A17: =A16+0.01 -> 12.13 | B17: Supply of Roof conductor holder for parapet- Polyamide Conductor holder: With M8 female thread or diameter 7mm, M8 Screw to connect the conductor holder.Weather and temperature resistant from -35 to +90 degree Celsius tested. Conductor holder @ 1 meter distance OBO Type No. 177 30 M8(5207460 ) | E17: Nos | F17: R.O
A18: =A17+0.01 -> 12.14 | B18: Supply of Test Joint suitable to connect 8mm round conductor and max by 30x3 mm GI strip as specified in drawing and directed by Engineer OBO Type No. 271 8-10 ( 5317401 ) | E18: Nos | F18: R.O
B19: Earthing
A20: =A18+0.01 -> 12.15 | B20: Supply of Galvanised Steel Flat 30X3 mm thickness from earth electrode directly in ground as required. Flat conductor Hot Dipped Galvanized. OBO Type No. 5052 DIN 30X3 ( 5450436 ) | E20: Mtr | F20: R.O
A21: =A20+0.01 -> 12.16 | B21: Providing of Cross connector for Flat: Suitable for 30mm Galvanised steel strip. Installed with 4 nos of hexagonal plate. OBO Type No. 255 A-FL30 FT (5314534 ) | E21: Nos | F21: R.O
A22: =A21+0.01 -> 12.17 | B22: Providing of flat conductor holder suitable for FL 30. Installed with 2 hexagonal bolts. OBO Type No. 166 LS 70 ( 5226570 ) | E22: Nos | F22: R.O
A23: =A22+0.01 -> 12.18 | B23: Providing of Plastic Corrosion Protection strip: Approx 1.1 mm thick. Width 50mm. Made of petrolatum- coated chemical fibre fabric. OBO Type No.356 50 ( 2360 05 5 ) | E23: Nos | F23: R.O
A24: =A23+0.01 -> 12.19 | B24: Supply of UL Listed & CPRI Tested maintenance free ,Low carbon copper coated earth rod of 3 metre electrode having diameter of 14 mm with copper coating thickness of 250micron tested as per IEC 62561-2 . OBO Type No. 14 3000 CCER(5450010) | E24: Nos | F24: R.O
A25: =A24+0.01 -> 12.2 | B25: Universal clamp made of SS to connect rod with flat conductor . OBO Type No. 14 25 RTC(5450066) | E25: Nos | F25: R.O
A26: =A25+0.01 -> 12.21 | B26: Earth conductivity enhancing compound shall be of 25 kg/pit tested as per IEC 62561-7,TCLP tested. OBO Type No. OEC 2 25(5450058) | E26: Nos | F26: R.O
A27: =A26+0.01 -> 12.22 | B27: The above arrangements shall be provided with Heavy duty earth champer of 5000kg load bearing capacity to ensure the safety of earthing system . OBO Type No.UFE(5450030). | E27: Nos | F27: R.O
B29: Total Part-12

Sheet FIRE -SUMMARY
A1: Subject | B1: : Fire BOQ - Summary
A3: Summary
A5: Part | B5: Description | C5: Supply Amount in INR | D5: Install Amount in INR | E5: Total Amount in INR
A8: A | B8: ='[2]FIRE BOQ'!B4 -> FIRE HYDRANT SYSTEM | C8: ='FIRE BOQ'!G59 -> 945460 | D8: ='FIRE BOQ'!H59 -> 173620 | E8: =D8+C8 -> 1119080
A10: B | B10: ='[2]FIRE BOQ'!B61 -> CIVIL WORKS | C10: ='FIRE BOQ'!G75 -> 13780 | D10: ='FIRE BOQ'!H75 -> 58295 | E10: =D10+C10 -> 72075
A12: C | B12: ='[2]FIRE BOQ'!B77 -> SIGNAGES ( @ Near Every access entry) | C12: ='FIRE BOQ'!G114 -> 80560 | D12: ='FIRE BOQ'!H114 -> 15900 | E12: =D12+C12 -> 96460
A14: D | B14: ='[2]FIRE BOQ'!B116 -> FIRE EXTINGUISHER SYSTEM | C14: ='FIRE BOQ'!G132 -> 201665 | D14: ='FIRE BOQ'!H132 -> 17490 | E14: =D14+C14 -> 219155
A16: E | B16: ='[2]FIRE BOQ'!B134 -> FIRE ALARM SYSTEM | C16: ='FIRE BOQ'!G168 -> 657897 | D16: ='FIRE BOQ'!H168 -> 111025 | E16: =D16+C16 -> 768922
A18: G | B18: ='[2]FIRE BOQ'!B170 -> PUMPS AND ANCILLARIES | C18: ='FIRE BOQ'!G213 -> 487110 | D18: ='FIRE BOQ'!H213 -> 75700 | E18: =D18+C18 -> 562810
A20: H | B20: ='[2]FIRE BOQ'!B172 -> Supply erection testing and commissioning of automatic centrifugal pumpset of approved make(End suction type) for giving discharge of 27 ltrs/sec @ 60M head .when running at suitable rpm when directly coupled to suitable HP TEFC motor to operate 400/440 volts 3 phase 50 cycles AC supply with a terminal box suitable for the reception of power cable termination, common base plate, necessary foundation bolts and accessories, pressure gauges, test valve connections, squirel cage for motor etc., all as per detailed specification. Rate quoted shall include necessary sluice valves(suction side) and butterfly & non return valves as required on suction , delvery and testline common header side ., etc complete. Priming tank requirement for the fire negative suction pump is as per the pump supplier's requirement. | C20: ='FIRE BOQ'!G266 -> 485600 | D20: ='FIRE BOQ'!H266 -> 135760 | E20: =D20+C20 -> 621360
B22: TOTAL | C22: =SUM(C7:C21) -> 2872072 | D22: =SUM(D7:D21) -> 587790 | E22: =SUM(E7:E21) -> 3459862 | F22: 3459000 | G22: =E22-F22 -> 862
B24: Assumptions & Exclusions
A25: 1 | B25: Construction of Over head fire water tank is excluded in the costing.
A26: 2 | B26: Excluding Approval and Laisioning related charges.
A27: 3 | B27: The costs indicated are exclusive of taxes .

Sheet FIRE BOQ
A1: Fire BOQ
B3: DESCRIPTION OF WORK | C3: Unit | D3: Qty | E3: Supply Rate in INR | F3: Install Rate in INR | G3: Supply Amount in INR | H3: Install Amount in INR
A4: A | B4: FIRE HYDRANT SYSTEM
A6: 1 | B6: UNDER GROUND PIPING
B7: Supply, erect, jointing, testing and commissioning heavy class G.I pipe (as per IS-1239) in trenches (1 Mtrs below ground level) with necessary supports at equal interval. Rate quoted shall include for necessary specials like long radius bends, tees, including cutting,welding / flanged joints with necessary washers, nuts, bolts,etc. Rate quoted shall also include for providing concrete anchor blocks (thrust block) at all change in direction of pipeline and also near each joints and also providing wrapping and costing for anticorrosive treatment as per specfication.
B8: PIPE TO EXTERNAL YARD HYDRANT
B9: a) 150 mm dia. (From Plant room to header line and from 2Way FBIC to header ) | C9: Rmt | D9: 30 | E9: 1775 | F9: 350 | G9: =E9*D9 -> 53250 | H9: =F9*D9 -> 10500
B10: b) 100 mm dia. (Ring main system) | C10: Rmt | D10: RO | E10: 0 | F10: 0 | G10: =E10*D10 -> 0 | H10: =F10*D10 -> 0
B11: c) 80 mm dia. (To Yard Hydrant valve) | C11: Rmt | D11: 10 | E11: =820 -> 820 | F11: 350 | G11: =E11*D11 -> 8200 | H11: =F11*D11 -> 3500
E12: 0 | F12: 0 | G12: =E12*D12 -> 0 | H12: =F12*D12 -> 0
A13: 2 | B13: PIPING ABOVE GROUND : | E13: 0 | F13: 0 | G13: =E13*D13 -> 0 | H13: =F13*D13 -> 0
B14: Supply, errect, jointing, testing and commissioning of heavy class G.I pipes (as per IS-1239). The pipes being fixed on to the wall or suspended from the ceiling / truss with angle iron supports complete with bends, tees, flanges and with all other required accessories including painting of the pipeline with two coats of approved enamel paint over a coat of anti corrosive primer etc. complete. As per IS code standards. | E14: 0 | F14: 0 | G14: =E14*D14 -> 0 | H14: =F14*D14 -> 0
B15: Rate quoted above shall include providing M.S.supports in angle iron / plates pipes etc. at every 2.5 m c/c. Rate quoted shall include for supply and providing necessary, welding cutting, 'U' clamps both nuts, washers etc.as per specification or pipe supports for horizontal / vertical pipes running along wall / column, slabs trenches etc to suit different dia pipes made of GI/MS rods, flats etc. consists of strap, nuts washers, threaded rod etc., rate quoted shall also include necessary aniti corrosive painting and 2 coat f approved enamel colour paint | E15: 0 | F15: 0 | G15: =E15*D15 -> 0 | H15: =F15*D15 -> 0
B16: a) 150 mm dia. ( Main header from OHT/ Pump room and running inside kitchen area ) | C16: Rmt | D16: 180 | E16: 1775 | F16: 350 | G16: =E16*D16 -> 319500 | H16: =F16*D16 -> 63000
B17: b) 80 mm dia. (To Internal Hydrant valve) | C17: Rmt | D17: 10 | E17: 820 | F17: 350 | G17: =E17*D17 -> 8200 | H17: =F17*D17 -> 3500
A18: 3 | B18: BUTTERFLY VALVE: | E18: 0 | F18: 0 | G18: =E18*D18 -> 0 | H18: =F18*D18 -> 0
B19: Supplying, Installing, testing and commissioning CI butterfly valves as per IS standard slim seal standard lever operated type with required flanges, nuts, bolts etc. complete. | E19: 0 | F19: 0 | G19: =E19*D19 -> 0 | H19: =F19*D19 -> 0
B20: PN-10 | E20: 0 | F20: 0 | G20: =E20*D20 -> 0 | H20: =F20*D20 -> 0
B21: a) 150 mm dia. (4 way brigade inlet) | C21: Nos | D21: RO | E21: 0 | F21: 0 | G21: =E21*D21 -> 0 | H21: =F21*D21 -> 0
B22: b) 150 mm dia. (2 way brigade inlet) | C22: Nos | D22: 2 | E22: 6500 | F22: 1500 | G22: =E22*D22 -> 13000 | H22: =F22*D22 -> 3000
B23: c) 150 mm dia. (Main distribution line) | C23: Nos | D23: 2 | E23: 6500 | F23: 1500 | G23: =E23*D23 -> 13000 | H23: =F23*D23 -> 3000
B24: d) 150 mm dia. - (@ Pump outlet) | C24: Nos | D24: 1 | E24: 6500 | F24: 1500 | G24: =E24*D24 -> 6500 | H24: =F24*D24 -> 1500
E25: 0 | F25: 0 | G25: =E25*D25 -> 0 | H25: =F25*D25 -> 0
A26: 4 | B26: NON RETURN VALVE : | E26: 0 | F26: 0 | G26: =E26*D26 -> 0 | H26: =F26*D26 -> 0
B27: Supply, fixing, testing and commissioning of CI Non return valve ( Dual plate type ) falnged end of approved brand of manufacture, with accressories,etc complete. PN:10 | E27: 0 | F27: 0 | G27: =E27*D27 -> 0 | H27: =F27*D27 -> 0
B28: a) 150 mm dia. - Terrace piping @ OHT outet | C28: Rmt | D28: 1 | E28: 7500 | F28: 1500 | G28: =E28*D28 -> 7500 | H28: =F28*D28 -> 1500
E29: 0 | F29: 0 | G29: =E29*D29 -> 0 | H29: =F29*D29 -> 0
A30: 5 | B30: AUTOMATIC AIR RELEASE VALVES : | E30: 0 | F30: 0 | G30: =E30*D30 -> 0 | H30: =F30*D30 -> 0
B31: Supply, fixing, testing and commissioning of Air release valves screwed ends of approved brand of manufacture, with accressories,etc complete- PN-10 | E31: 0 | F31: 0 | G31: =E31*D31 -> 0 | H31: =F31*D31 -> 0
B32: 25 mm dia. | C32: Nos | D32: 3 | E32: 3710 | F32: 530 | G32: =E32*D32 -> 11130 | H32: =F32*D32 -> 1590
E33: 0 | F33: 0 | G33: =E33*D33 -> 0 | H33: =F33*D33 -> 0
A34: 6 | B34: BALL VALVE (for arv) | E34: 0 | F34: 0 | G34: =E34*D34 -> 0 | H34: =F34*D34 -> 0
B35: Supplying, installing, testing and commissioning of heavy duty Gun Metal gate valves screwed ends of approved brand of manufacture. PN-10 | E35: 0 | F35: 0 | G35: =E35*D35 -> 0 | H35: =F35*D35 -> 0
B36: a) 25 mm dia. | C36: Nos | D36: 1 | E36: 3180 | F36: 530 | G36: =E36*D36 -> 3180 | H36: =F36*D36 -> 530
E37: 0 | F37: 0 | G37: =E37*D37 -> 0 | H37: =F37*D37 -> 0
A38: 7 | B38: INTERNAL FIRE HYDRANT SYSTEM : | E38: 0 | F38: 0 | G38: =E38*D38 -> 0 | H38: =F38*D38 -> 0
B39: SINGLE HEADED INTERNAL & YARD HYDRANT : | E39: 0 | F39: 0 | G39: =E39*D39 -> 0 | H39: =F39*D39 -> 0
B40: Supply, fix, test and commissioning of the following :- | E40: 0 | F40: 0 | G40: =E40*D40 -> 0 | H40: =F40*D40 -> 0
B41: a) 80 mm dia GI MSDF bend.80 mm dia GI MSDF stand pipe (1 Mtr below + 1 Mtr above).The pipe portion below ground shall be with anti corrosive treatment as per detail specifications | C41: Nos | D41: 2 | E41: 5500 | F41: 1000 | G41: =E41*D41 -> 11000 | H41: =F41*D41 -> 2000
B42: b) 1 No. 63 mm dia female instantaneous pattern oblique hydrant valve with chain and cap of gun metal | C42: Nos | D42: 4 | E42: 5500 | F42: 1000 | G42: =E42*D42 -> 22000 | H42: =F42*D42 -> 4000
...

Sheet MAKES
A1: Subject | B1: : Fire Prefered makes
A2: FPS - PREFERED MAKES
A3: 1 | B3: FIRE PUMPS | C3: KIRLOSKAR /WILO /GRUNDFOS/XYLUM
A4: 2 | B4: DIESEL ENGINE | C4: KIRLOSKAR OIL ENGINE /CUMMINS INDIA/CLARKE
A5: 3 | B5: G.I./ M.S. PIPES | C5: JINDAL( HISSAR)/ JINDAL (STAR) / TATA
A6: 4 | B6: PIPE FITTINGS | C6: SANJAY FORGE / GOYAL / B & M
A7: 5 | B7: BUTTERFLY VALES | C7: AUDCO / ADVANCE / INTERVALVE
A8: 6 | B8: NON – RETURN VALVES | C8: AUDCO / KIRLOSKER / H. SARKER
A9: 7 | B9: GATE VALVES | C9: NVR / ZOLOTO /LEADER / NETA
A10: 8 | B10: BALL VALES | C10: NVR / ZOLOTO / LEADER / NETA
A11: 9 | B11: STRAINERS | C11: H. SARKER / UPADYA / KALPANA
A12: 10 | B12: C.I. GATE VALVES | C12: H. SARKER / CRESENT / KALPANA
A13: 11 | B13: FOOT VALVES | C13: NORMEX / KIRLOSKAR/ EQUI.
A14: 12 | B14: FLOW METRE | C14: FORBES MARSHALL / EUREKA
... A33: 31 | B33: PRESSURE REDUCING VALVE | C33: LEHRY/ZOLOTO / NVR
B35: FIRE -RELATED ELECTRICAL WORKS
A36: 1 | B36: ELECTRIC MOTORS | C36: KIRLOSKAR ELECTRIC / CROMPTON
C37: GREAVES / SIEMENS / ABB
A38: 2 | B38: BATTERY | C38: EXIDE / STANDARD / AMAR RAJA/MINIMAX
A39: 3 | B39: MOTOR CONTROL CENTRE | C39: RJMS / LOAD CONTROLS / PACE
A40: 4 | B40: CONTROL / POWER CABLES | C40: GLOSTER / UNIVERSAL / ASIAN / CCI/FINOLEX
A41: 5 | B41: MCCB | C41: L&T / MERLINGERIN / ABB / C&S
A42: 6 | B42: CONTROL MCB | C42: ABB/ MERLINGERIN / SIEMENS / LEGRAND
A43: 7 | B43: VOLT METER SELECT SWITCH | C43: SALZER / L & T / KAYCEE
A44: 8 | B44: VOLTMETER ( AC / DC) | C44: ELTRAC/TRINITY/CONZERVE
A45: 9 | B45: AMMETER ( AC / DC) | C45: ELTRAC/TRINITY/CONZERVE
A46: 10 | B46: POWER CONTACTORS | C46: L&T / MERLINGERIN / ABB / C&S
A47: 11 | B47: INDICATING LAPS (LED type) | C47: BINAY / TEKNIC / VAISHNO
A48: 12 | B48: PUSH BUTTONS | C48: TEKNIC / SIEMENS / VAISHNO
A49: 13 | B49: AUTO / MANUAL SELECTOR | C49: SALZER / KAYCEE / VAISHNO
... A62: 26 | B62: CABLE TRAY | C62: STORACK / PAN / MAG / REPUTED
B64: FIRE DETECTION & ALARM WITH P.A.SYSTEM
A65: 1 | B65: ADDS.MAIN CONTROL PANEL | C65: RAVEL OR EQUIVALENT MAKE
A66: 2 | B66: ADDS.MANUAL CALL POINTS | C66: RAVEL OR EQUIVALENT MAKE
A67: 3 | B67: ADDS.ELECTRONIC HOOTERS | C67: RAVEL OR EQUIVALENT MAKE
A68: 4 | B68: ADD.COMBINATION DETECTOR | C68: RAVEL OR EQUIVALENT MAKE
A69: 5 | B69: ADD.HEAT DETECTOR | C69: RAVEL OR EQUIVALENT MAKE
A70: 6 | B70: DUCT DETECTOR | C70: RAVEL OR EQUIVALENT MAKE
A71: 7 | B71: BEAM DETECTOR | C71: RAVEL OR EQUIVALENT MAKE
A72: 8 | B72: MONITOR MODULE | C72: RAVEL OR EQUIVALENT MAKE
...
